Traceback (most recent call last):
  File "C:\Users\sayala\AppData\Roaming\Python\Python311\site-packages\jupyter_cache\executors\utils.py", line 58, in single_nb_execution
    executenb(
  File "C:\ProgramData\Anaconda3\Lib\site-packages\nbclient\client.py", line 1204, in execute
    return NotebookClient(nb=nb, resources=resources, km=km, **kwargs).execute()
           ^^^^^^^^^^^^^^^^^^^^^^^^^^^^^^^^^^^^^^^^^^^^^^^^^^^^^^^^^^^^^^^^^^^^^
  File "C:\ProgramData\Anaconda3\Lib\site-packages\nbclient\util.py", line 84, in wrapped
    return just_run(coro(*args, **kwargs))
           ^^^^^^^^^^^^^^^^^^^^^^^^^^^^^^^
  File "C:\ProgramData\Anaconda3\Lib\site-packages\nbclient\util.py", line 62, in just_run
    return loop.run_until_complete(coro)
           ^^^^^^^^^^^^^^^^^^^^^^^^^^^^^
  File "C:\ProgramData\Anaconda3\Lib\asyncio\base_events.py", line 653, in run_until_complete
    return future.result()
           ^^^^^^^^^^^^^^^
  File "C:\ProgramData\Anaconda3\Lib\site-packages\nbclient\client.py", line 663, in async_execute
    await self.async_execute_cell(
  File "C:\ProgramData\Anaconda3\Lib\site-packages\nbclient\client.py", line 965, in async_execute_cell
    await self._check_raise_for_error(cell, cell_index, exec_reply)
  File "C:\ProgramData\Anaconda3\Lib\site-packages\nbclient\client.py", line 862, in _check_raise_for_error
    raise CellExecutionError.from_cell_and_msg(cell, exec_reply_content)
nbclient.exceptions.CellExecutionError: An error occurred while executing the following cell:
------------------
testfolder = 'Second'

if not os.path.exists(testfolder):
    os.makedirs(testfolder)
------------------

[1;31m---------------------------------------------------------------------------[0m
[1;31mNameError[0m                                 Traceback (most recent call last)
Cell [1;32mIn[4], line 3[0m
[0;32m      1[0m testfolder [38;5;241m=[39m [38;5;124m'[39m[38;5;124mSecond[39m[38;5;124m'[39m
[1;32m----> 3[0m [38;5;28;01mif[39;00m [38;5;129;01mnot[39;00m os[38;5;241m.[39mpath[38;5;241m.[39mexists(testfolder):
[0;32m      4[0m     os[38;5;241m.[39mmakedirs(testfolder)

[1;31mNameError[0m: name 'os' is not defined
NameError: name 'os' is not defined

